<?xml version="1.0" ?>
<!-- PuzzleBot differential drive -->
<robot name="puzzlebot" xmlns:xacro="http://www.ros.org/wiki/xacro">

<!-- files for gazebo costumization -->

<xacro:include filename="$(find puzzlebot_gazebo)/urdf/parameters.xacro" />
<xacro:include filename="$(find puzzlebot_gazebo)/urdf/macros.xacro" />

<xacro:include filename="$(find puzzlebot_gazebo)/urdf/puzzlebot.gazebo" />
<xacro:include filename="$(find puzzlebot_gazebo)/urdf/materials.xacro" />
 

<!-- Dummy link needed to load the model properly-->
  <link name="base_link">
    <pose>0 0 0 0 0 0</pose>
  </link>
  
  <link name="chassis">
    <pose>0 0 0 0 0 0</pose>
    <visual>
      <!-- with basic geometric shapes  
      <origin xyz="0 0 0" rpy="0 0 0"/> 
          <geometry>
          	  <box size="${chassisX} ${chassisY} ${chassisZ}"/> 
          </geometry>-->
       <!-- with mesh  -->
        <origin xyz="0 0 0" rpy="${PI/2} 0 ${PI/2}"/>
          <geometry>
          	 <mesh filename="file://${mesh_chassis}"/>
          </geometry> 
     
    </visual>
    <collision name="collision_chassis">
    	<origin rpy="0 0 0" xyz="0 0 0"/>
          <geometry>
            	 <box size="${chassisX} ${chassisY} ${chassisZ}"/> 
          </geometry>
    </collision>
    <inertial>
      <mass value="${chassisMass}"/>    
      <xacro:box_inertia m="${chassisMass}" x="${chassisX}" y="${chassisY}" z="${chassisZ}" />
    </inertial>

   <!--  caster wheel attached to frame --> 
    <collision>
	    <origin xyz="-0.095 0 -0.0425" rpy="0 0 0"/>
		  <geometry>
		     <sphere radius="${casterRadius}"/>
		  </geometry>
		   <surface>
	      <friction>
	         <ode>
	          <slip1>0.0</slip1>
	          <slip2>0.0</slip2>
	         </ode>
	      </friction>
      </surface>
	  </collision>
	  <visual>
      <origin xyz="-0.095 0 -0.0425" rpy="0 0 0"/>
          <geometry>
          	   <sphere radius="${casterRadius}"/>
          </geometry>
    </visual>
  </link>

 <joint name="base_link_to_chassis" type="fixed">
	   <parent link="base_link"/>
	   <child link="chassis"/>
  </joint>

<!-- TASK 1a - create the shape needed for the wheel specified in  -->
 
<!-- TASK 1b -  -->
	<xacro:wheel prefix="right" reflect="-1"/>
	<xacro:wheel prefix="left"  reflect="1"/>
	
<!-- THE COMMENT TASK WILL BE REMOVE UNTIL TASK 1 IS FINISHED --> 
<!-- JOINTS   --> 
  <joint name="base_to_right_w" type="continuous">
	  <parent link="chassis" />
	  <child link="right_wheel" />
	  <origin xyz="0.05 -0.09 0.0" />
		<axis xyz="0 1 0" rpy="0 0 0" />
	</joint>

	<joint name="base_to_left_w" type="continuous">
	  <parent link="chassis" />
	  <child link="left_wheel" />
	  <origin xyz="0.05 0.09 0" />
	  <axis xyz="0 1 0" rpy="0 0 0" />
	</joint>

<!-- TASK 2a - Add transmissions -->
<!-- TRANSMISSIONS (For a more complex model and it represents actuator attributes) -->
<transmission name="right_wheel_trans">
    <type>transmission_interface/SimpleTransmission</type>
    <joint name="base_to_right_w">
    	<hardwareInterface>hardware_interface/VelocityJointInterface</hardwareInterface>
    </joint>
    <actuator name="right_wheel_motor">
      <mechanicalReduction>34</mechanicalReduction>
       <hardwareInterface>hardware_interface/VelocityJointInterface</hardwareInterface>
    </actuator>
  </transmission>

<transmission name="left_wheel_trans">
    <type>transmission_interface/SimpleTransmission</type>
    <joint name="base_to_left_w">
    	<hardwareInterface>hardware_interface/VelocityJointInterface</hardwareInterface>
    </joint>
    <actuator name="left_wheel_motor">
      <mechanicalReduction>34</mechanicalReduction>
      <hardwareInterface>hardware_interface/VelocityJointInterface</hardwareInterface>
    </actuator>
</transmission>  

</robot>